<?xml version="1.0" ?>
<!-- =================================================================================== -->
<!-- |    This document was autogenerated by xacro from xacro/cubebot_3D.xacro         | -->
<!-- |    EDITING THIS FILE BY HAND IS NOT RECOMMENDED                                 | -->
<!-- =================================================================================== -->
<robot name="test" xmlns:xacro="http://ros.org/wiki/xacro">
  <link name="CubeBody">
    <visual>
      <origin rpy="0 0 0" xyz="0 0 0"/>
      <geometry>
        <box size="1.0 1.0 1.0"/>
      </geometry>
      <material name="Blue">
        <color rgba=".0157 .1176 .2588 1"/>
      </material>
    </visual>
    <collision>
      <origin rpy="0 0 0" xyz="0 0 0"/>
      <geometry>
        <box size="1.0 1.0 1.0"/>
      </geometry>
      <!-- <contact_coefficient mu="0"  resitution="0"  k_p="0"  k_d="0" /> -->
    </collision>
    <inertial>
      <origin rpy="0 0 0" xyz="0 0 0"/>
      <mass value="0.0"/>
      <inertia ixx="0.5" ixy="0" ixz="0" iyy="0.5" iyz="0.0" izz="0.5"/>
    </inertial>
  </link>
  <link name="CornerBumper_1">
    <visual>
      <origin rpy="0 0 0" xyz="0 0 0"/>
      <geometry>
        <sphere radius="0.01"/>
      </geometry>
      <material name="Green">
        <color rgba="0.1 0.8 0.1 1"/>
      </material>
    </visual>
    <collision>
      <origin rpy="0 0 0" xyz="0 0 0"/>
      <geometry>
        <sphere radius="0.01"/>
      </geometry>
      <!-- <contact_coefficient mu="0"  resitution="0"  k_p="0"  k_d="0" /> -->
    </collision>
    <inertial>
      <origin rpy="0 0 0" xyz="0 0 0"/>
      <mass value="1.0"/>
      <inertia ixx="0.0" ixy="0" ixz="0" iyy="0.0" iyz="0.0" izz="0.0"/>
    </inertial>
  </link>
  <link name="CornerBumper_2">
    <visual>
      <origin rpy="0 0 0" xyz="0 0 0"/>
      <geometry>
        <sphere radius="0.01"/>
      </geometry>
      <material name="Orange">
        <color rgba=".9569 .5372 .2588 1"/>
      </material>
    </visual>
    <collision>
      <origin rpy="0 0 0" xyz="0 0 0"/>
      <geometry>
        <sphere radius="0.01"/>
      </geometry>
      <!-- <contact_coefficient mu="0"  resitution="0"  k_p="0"  k_d="0" /> -->
    </collision>
    <inertial>
      <origin rpy="0 0 0" xyz="0 0 0"/>
      <mass value="1.0"/>
      <inertia ixx="0.0" ixy="0" ixz="0" iyy="0.0" iyz="0.0" izz="0.0"/>
    </inertial>
  </link>
  <link name="CornerBumper_3">
    <visual>
      <origin rpy="0 0 0" xyz="0 0 0"/>
      <geometry>
        <sphere radius="0.01"/>
      </geometry>
      <material name="Orange">
        <color rgba=".9569 .5372 .2588 1"/>
      </material>
    </visual>
    <collision>
      <origin rpy="0 0 0" xyz="0 0 0"/>
      <geometry>
        <sphere radius="0.01"/>
      </geometry>
      <!-- <contact_coefficient mu="0"  resitution="0"  k_p="0"  k_d="0" /> -->
    </collision>
    <inertial>
      <origin rpy="0 0 0" xyz="0 0 0"/>
      <mass value="1.0"/>
      <inertia ixx="0.0" ixy="0" ixz="0" iyy="0.0" iyz="0.0" izz="0.0"/>
    </inertial>
  </link>
  <link name="CornerBumper_4">
    <visual>
      <origin rpy="0 0 0" xyz="0 0 0"/>
      <geometry>
        <sphere radius="0.01"/>
      </geometry>
      <material name="Orange">
        <color rgba=".9569 .5372 .2588 1"/>
      </material>
    </visual>
    <collision>
      <origin rpy="0 0 0" xyz="0 0 0"/>
      <geometry>
        <sphere radius="0.01"/>
      </geometry>
      <!-- <contact_coefficient mu="0"  resitution="0"  k_p="0"  k_d="0" /> -->
    </collision>
    <inertial>
      <origin rpy="0 0 0" xyz="0 0 0"/>
      <mass value="1.0"/>
      <inertia ixx="0.0" ixy="0" ixz="0" iyy="0.0" iyz="0.0" izz="0.0"/>
    </inertial>
  </link>
  <link name="CornerBumper_5">
    <visual>
      <origin rpy="0 0 0" xyz="0 0 0"/>
      <geometry>
        <sphere radius="0.01"/>
      </geometry>
      <material name="Orange">
        <color rgba=".9569 .5372 .2588 1"/>
      </material>
    </visual>
    <collision>
      <origin rpy="0 0 0" xyz="0 0 0"/>
      <geometry>
        <sphere radius="0.01"/>
      </geometry>
      <!-- <contact_coefficient mu="0"  resitution="0"  k_p="0"  k_d="0" /> -->
    </collision>
    <inertial>
      <origin rpy="0 0 0" xyz="0 0 0"/>
      <mass value="1.0"/>
      <inertia ixx="0.0" ixy="0" ixz="0" iyy="0.0" iyz="0.0" izz="0.0"/>
    </inertial>
  </link>
  <link name="CornerBumper_6">
    <visual>
      <origin rpy="0 0 0" xyz="0 0 0"/>
      <geometry>
        <sphere radius="0.01"/>
      </geometry>
      <material name="Orange">
        <color rgba=".9569 .5372 .2588 1"/>
      </material>
    </visual>
    <collision>
      <origin rpy="0 0 0" xyz="0 0 0"/>
      <geometry>
        <sphere radius="0.01"/>
      </geometry>
      <!-- <contact_coefficient mu="0"  resitution="0"  k_p="0"  k_d="0" /> -->
    </collision>
    <inertial>
      <origin rpy="0 0 0" xyz="0 0 0"/>
      <mass value="1.0"/>
      <inertia ixx="0.0" ixy="0" ixz="0" iyy="0.0" iyz="0.0" izz="0.0"/>
    </inertial>
  </link>
  <link name="CornerBumper_7">
    <visual>
      <origin rpy="0 0 0" xyz="0 0 0"/>
      <geometry>
        <sphere radius="0.01"/>
      </geometry>
      <material name="Orange">
        <color rgba=".9569 .5372 .2588 1"/>
      </material>
    </visual>
    <collision>
      <origin rpy="0 0 0" xyz="0 0 0"/>
      <geometry>
        <sphere radius="0.01"/>
      </geometry>
      <!-- <contact_coefficient mu="0"  resitution="0"  k_p="0"  k_d="0" /> -->
    </collision>
    <inertial>
      <origin rpy="0 0 0" xyz="0 0 0"/>
      <mass value="1.0"/>
      <inertia ixx="0.0" ixy="0" ixz="0" iyy="0.0" iyz="0.0" izz="0.0"/>
    </inertial>
  </link>
  <link name="CornerBumper_8">
    <visual>
      <origin rpy="0 0 0" xyz="0 0 0"/>
      <geometry>
        <sphere radius="0.01"/>
      </geometry>
      <material name="Orange">
        <color rgba=".9569 .5372 .2588 1"/>
      </material>
    </visual>
    <collision>
      <origin rpy="0 0 0" xyz="0 0 0"/>
      <geometry>
        <sphere radius="0.01"/>
      </geometry>
      <!-- <contact_coefficient mu="0"  resitution="0"  k_p="0"  k_d="0" /> -->
    </collision>
    <inertial>
      <origin rpy="0 0 0" xyz="0 0 0"/>
      <mass value="1.0"/>
      <inertia ixx="0.0" ixy="0" ixz="0" iyy="0.0" iyz="0.0" izz="0.0"/>
    </inertial>
  </link>
  <link name="InertialWheel_1">
    <visual>
      <origin rpy="0 0 0" xyz="0 0 0.0"/>
      <geometry>
        <cylinder length="0.1" radius="0.2"/>
      </geometry>
      <material name="Purple">
        <color rgba="0.8 0.1 0.8 1"/>
      </material>
    </visual>
    <collision>
      <origin rpy="0 0 0" xyz="0 0 0.0"/>
      <geometry>
        <cylinder length="0.1" radius="0.25"/>
      </geometry>
      <!-- <contact_coefficient mu="0"  resitution="0"  k_p="0"  k_d="0" /> -->
    </collision>
    <inertial>
      <origin rpy="0 0 0" xyz="0 0 0.0"/>
      <mass value="0.1"/>
      <inertia ixx="0.0013333333333333335" ixy="0" ixz="0" iyy="0.0013333333333333335" iyz="0.0" izz="0.0025000000000000005"/>
    </inertial>
  </link>
  <link name="InertialWheel_2">
    <visual>
      <origin rpy="0 0 0" xyz="0 0 0.0"/>
      <geometry>
        <cylinder length="0.1" radius="0.2"/>
      </geometry>
      <material name="Purple">
        <color rgba="0.8 0.1 0.8 1"/>
      </material>
    </visual>
    <collision>
      <origin rpy="0 0 0" xyz="0 0 0.0"/>
      <geometry>
        <cylinder length="0.1" radius="0.25"/>
      </geometry>
      <!-- <contact_coefficient mu="0"  resitution="0"  k_p="0"  k_d="0" /> -->
    </collision>
    <inertial>
      <origin rpy="0 0 0" xyz="0 0 0.0"/>
      <mass value="0.1"/>
      <inertia ixx="0.0013333333333333335" ixy="0" ixz="0" iyy="0.0013333333333333335" iyz="0.0" izz="0.0025000000000000005"/>
    </inertial>
  </link>
  <link name="InertialWheel_3">
    <visual>
      <origin rpy="0 0 0" xyz="0 0 0.0"/>
      <geometry>
        <cylinder length="0.1" radius="0.2"/>
      </geometry>
      <material name="Purple">
        <color rgba="0.8 0.1 0.8 1"/>
      </material>
    </visual>
    <collision>
      <origin rpy="0 0 0" xyz="0 0 0.0"/>
      <geometry>
        <cylinder length="0.1" radius="0.25"/>
      </geometry>
      <!-- <contact_coefficient mu="0"  resitution="0"  k_p="0"  k_d="0" /> -->
    </collision>
    <inertial>
      <origin rpy="0 0 0" xyz="0 0 0.0"/>
      <mass value="0.1"/>
      <inertia ixx="0.0013333333333333335" ixy="0" ixz="0" iyy="0.0013333333333333335" iyz="0.0" izz="0.0025000000000000005"/>
    </inertial>
  </link>
  <link name="InertialWheel_4">
    <visual>
      <origin rpy="0 0 0" xyz="0 0 0.0"/>
      <geometry>
        <cylinder length="0.1" radius="0.2"/>
      </geometry>
      <material name="Purple">
        <color rgba="0.8 0.1 0.8 1"/>
      </material>
    </visual>
    <collision>
      <origin rpy="0 0 0" xyz="0 0 0.0"/>
      <geometry>
        <cylinder length="0.1" radius="0.25"/>
      </geometry>
      <!-- <contact_coefficient mu="0"  resitution="0"  k_p="0"  k_d="0" /> -->
    </collision>
    <inertial>
      <origin rpy="0 0 0" xyz="0 0 0.0"/>
      <mass value="0.1"/>
      <inertia ixx="0.0013333333333333335" ixy="0" ixz="0" iyy="0.0013333333333333335" iyz="0.0" izz="0.0025000000000000005"/>
    </inertial>
  </link>
  <link name="InertialWheel_5">
    <visual>
      <origin rpy="0 0 0" xyz="0 0 0.0"/>
      <geometry>
        <cylinder length="0.1" radius="0.2"/>
      </geometry>
      <material name="Purple">
        <color rgba="0.8 0.1 0.8 1"/>
      </material>
    </visual>
    <collision>
      <origin rpy="0 0 0" xyz="0 0 0.0"/>
      <geometry>
        <cylinder length="0.1" radius="0.25"/>
      </geometry>
      <!-- <contact_coefficient mu="0"  resitution="0"  k_p="0"  k_d="0" /> -->
    </collision>
    <inertial>
      <origin rpy="0 0 0" xyz="0 0 0.0"/>
      <mass value="0.1"/>
      <inertia ixx="0.0013333333333333335" ixy="0" ixz="0" iyy="0.0013333333333333335" iyz="0.0" izz="0.0025000000000000005"/>
    </inertial>
  </link>
  <link name="InertialWheel_6">
    <visual>
      <origin rpy="0 0 0" xyz="0 0 0.0"/>
      <geometry>
        <cylinder length="0.1" radius="0.2"/>
      </geometry>
      <material name="Purple">
        <color rgba="0.8 0.1 0.8 1"/>
      </material>
    </visual>
    <collision>
      <origin rpy="0 0 0" xyz="0 0 0.0"/>
      <geometry>
        <cylinder length="0.1" radius="0.25"/>
      </geometry>
      <!-- <contact_coefficient mu="0"  resitution="0"  k_p="0"  k_d="0" /> -->
    </collision>
    <inertial>
      <origin rpy="0 0 0" xyz="0 0 0.0"/>
      <mass value="0.1"/>
      <inertia ixx="0.0013333333333333335" ixy="0" ixz="0" iyy="0.0013333333333333335" iyz="0.0" izz="0.0025000000000000005"/>
    </inertial>
  </link>
  <joint name="$fixed_{parent}_CornerBumper_1" type="fixed">
    <origin rpy="0 0 0" xyz="0.5 0.5 0.5"/>
    <parent link="CubeBody"/>
    <child link="CornerBumper_1"/>
  </joint>
  <joint name="$fixed_{parent}_CornerBumper_2" type="fixed">
    <origin rpy="0 0 0" xyz="-0.5 0.5 0.5"/>
    <parent link="CubeBody"/>
    <child link="CornerBumper_2"/>
  </joint>
  <joint name="$fixed_{parent}_CornerBumper_3" type="fixed">
    <origin rpy="0 0 0" xyz="0.5 -0.5 0.5"/>
    <parent link="CubeBody"/>
    <child link="CornerBumper_3"/>
  </joint>
  <joint name="$fixed_{parent}_CornerBumper_4" type="fixed">
    <origin rpy="0 0 0" xyz="-0.5 -0.5 0.5"/>
    <parent link="CubeBody"/>
    <child link="CornerBumper_4"/>
  </joint>
  <joint name="$fixed_{parent}_CornerBumper_5" type="fixed">
    <origin rpy="0 0 0" xyz="0.5 0.5 -0.5"/>
    <parent link="CubeBody"/>
    <child link="CornerBumper_5"/>
  </joint>
  <joint name="$fixed_{parent}_CornerBumper_6" type="fixed">
    <origin rpy="0 0 0" xyz="-0.5 0.5 -0.5"/>
    <parent link="CubeBody"/>
    <child link="CornerBumper_6"/>
  </joint>
  <joint name="$fixed_{parent}_CornerBumper_7" type="fixed">
    <origin rpy="0 0 0" xyz="0.5 -0.5 -0.5"/>
    <parent link="CubeBody"/>
    <child link="CornerBumper_7"/>
  </joint>
  <joint name="$fixed_{parent}_CornerBumper_8" type="fixed">
    <origin rpy="0 0 0" xyz="-0.5 -0.5 -0.5"/>
    <parent link="CubeBody"/>
    <child link="CornerBumper_8"/>
  </joint>
  <joint name="$continuous_{parent}_InertialWheel_1" type="continuous">
    <origin rpy="0 1.57075 0" xyz="0.4 0 0"/>
    <parent link="CubeBody"/>
    <child link="InertialWheel_1"/>
    <axis xyz="0 0 1"/>
    <dynamics damping="0" friction="0"/>
  </joint>
  <joint name="$continuous_{parent}_InertialWheel_2" type="continuous">
    <origin rpy="0 1.57075 0" xyz="-0.4 0 0"/>
    <parent link="CubeBody"/>
    <child link="InertialWheel_2"/>
    <axis xyz="0 0 1"/>
    <dynamics damping="0" friction="0"/>
  </joint>
  <joint name="$continuous_{parent}_InertialWheel_3" type="continuous">
    <origin rpy="1.57075 0 0" xyz="0 0.4 0"/>
    <parent link="CubeBody"/>
    <child link="InertialWheel_3"/>
    <axis xyz="0 0 1"/>
    <dynamics damping="0" friction="0"/>
  </joint>
  <joint name="$continuous_{parent}_InertialWheel_4" type="continuous">
    <origin rpy="1.57075 0 0" xyz="0 -0.4 0"/>
    <parent link="CubeBody"/>
    <child link="InertialWheel_4"/>
    <axis xyz="0 0 1"/>
    <dynamics damping="0" friction="0"/>
  </joint>
  <joint name="$continuous_{parent}_InertialWheel_5" type="continuous">
    <origin rpy="0 0 1.57075" xyz="0 0 0.4"/>
    <parent link="CubeBody"/>
    <child link="InertialWheel_5"/>
    <axis xyz="0 0 1"/>
    <dynamics damping="0" friction="0"/>
  </joint>
  <joint name="$continuous_{parent}_InertialWheel_6" type="continuous">
    <origin rpy="0 0 1.57075" xyz="0 0 -0.4"/>
    <parent link="CubeBody"/>
    <child link="InertialWheel_6"/>
    <axis xyz="0 0 1"/>
    <dynamics damping="0" friction="0"/>
  </joint>
</robot>

