<?xml version="1.0"?>
<robot name="cubebot">
    <material name="black">
        <color rgba="0 0 0 1"/>
    </material>
    <material name="blue">
        <color rgba="0.2 0.2 0.8 0.8"/>
    </material>
    <material name="red">
        <color rgba="0.8 0.2 0.2 0.8"/>
    </material>
    <material name="green">
        <color rgba="0.2 0.8 0.2 0.8"/>
    </material>

    <!-- Used for fixing robot' -->
    <link name="world"/>
    
    <!-- Base Frame of Cube -->
    <link name="base">
        <visual>
            <origin xyz="0 0 0" rpy="0 0 0"/>
            <geometry>
                <box size="2.0 2.0 0.1"/>
            </geometry>
            <material name="red"/>
        </visual>

        <collision>
            <origin xyz="0 0 0" rpy="0 0 0"/>
            <geometry>
                <box size="2.0 2.0 0.1"/>
            </geometry>
            <!-- <contact_coefficient mu="0"  resitution="0"  k_p="0"  k_d="0" /> -->
        </collision>

        <inertial>
            <origin xyz="0 0 0" rpy="0 0 0"/>
            <mass value="100"/>
            <inertia ixx="1.0" ixy="0" ixz="0" iyy="1.0" iyz="0.0" izz="=1.0"/>
        </inertial>
    </link>

    <!-- Cube of Cube -->
   <link name="cube">
        <visual>
            <origin xyz="0 0.5 0.5" rpy="0 0 0"/>
            <geometry>
                <box size="1.0 1.0 1.0"/>
            </geometry>
            <material name="blue"/>
        </visual>

        <collision>
            <origin xyz="0 0.5 0.5" rpy="0 0 0"/>
            <geometry>
                <box size="1.0 1.0 1.0"/>
            </geometry>
            <!-- <contact_coefficient mu="0"  resitution="0"  k_p="0"  k_d="0" /> -->
        </collision>

        <inertial>
            <origin xyz="0 0.5 0.5" rpy="0 0 0"/>
            <mass value="0.01"/>
            <inertia ixx="0.01" ixy="0" ixz="0" iyy="0.01" iyz="0.0" izz="0.01"/>
        </inertial>
    </link>

    <!-- Inertial Wheel -->
    <link name="wheel">
        <visual>
            <origin xyz="0 0 0.05" rpy="0 0 0"/>
            <geometry>
                <cylinder length="0.1" radius="0.25"/>
            </geometry>
            <material name="green"/>
        </visual>

        <collision>
            <origin xyz="0 0 0.05" rpy="0 0 0"/>
            <geometry>
                <cylinder length="0.1" radius="0.25"/>
            </geometry>
            <!-- <contact_coefficient mu="0"  resitution="0"  k_p="0"  k_d="0" /> -->
        </collision>

        <inertial>
            <origin xyz="0 0 0.05" rpy="0 0 0"/>
            <mass value="1.0"/>
            <inertia ixx="1.0" ixy="0" ixz="0" iyy="1.0" iyz="0.0" izz="1.0"/>
        </inertial>
    </link>

    <joint name="fixed" type="fixed">
        <parent link="world"/>
        <child link="base"/>
    </joint>

    <joint name="base to cube" type="revolute">
        <origin xyz="0 0 0.05" rpy="0 0 0" />
        <parent link="base"/>
        <child link="cube"/>
        <limit effort="1" lower="0.0" upper="1.57075" velocity="10"/>
        <axis xyz="1 0 0"/>
        <!-- <calibration rising="0.0"/> -->
        <!-- <dynamics damping="0.0" friction="0.0"/> -->
        <!-- <limit effort="30" velocity="1.0" lower="-2.2" upper="0.7" />
        <safety_controller k_velocity="10" k_position="15" soft_lower_limit="-2.0" soft_upper_limit="0.5" /> -->

        <!-- <axis xyz="0.0 0.0 0.0"/> -->
    </joint>

    <joint name="cube to wheel" type="continuous">
        <origin xyz="0.5 0.5 0.5" rpy="0 1.57075 0" />
        <parent link="cube"/>
        <child link="wheel"/>
        <axis xyz="0 0 1"/>
        <dynamics damping="0.0" friction="0.0"/>
        
    </joint>

</robot>