<?xml version="1.0"?>
<robot name="cubebot">
    <material name="black">
        <color rgba="0 0 0 1"/>
    </material>
    <material name="blue">
        <color rgba="0.2 0.2 0.8 0.8"/>
    </material>
    <material name="red">
        <color rgba="0.8 0.2 0.2 0.8"/>
    </material>
    <material name="green">
        <color rgba="0.2 0.8 0.2 0.8"/>
    </material>

    <!-- Used for fixing robot' -->
    <link name="world"/>
    
    <!-- Used for fixing robot' -->
    <link name="intermediate"/>

    <!-- Pole -->
    <link name="pole">
        <visual>
            <origin xyz="0 0 0.5" rpy="0 0 0"/>
            <geometry>
                <cylinder length="1.0" radius="0.05"/>
            </geometry>
            <material name="red"/>
        </visual>

        <collision>
            <origin xyz="0 0 0.5" rpy="0 0 0"/>
            <geometry>
                <cylinder length="1.0" radius="0.05"/>
            </geometry>
            <!-- <contact_coefficient mu="0"  resitution="0"  k_p="0"  k_d="0" /> -->
        </collision>

        <inertial>
            <origin xyz="0 0 0.5" rpy="0 0 0"/>
            <mass value="0.1"/>
            <inertia ixx="0.1" ixy="0" ixz="0" iyy="0.1" iyz="0.0" izz="=0.1"/>
        </inertial>
    </link>

    <!-- Inertial Wheel -->
    <link name="wheel">
        <visual>
            <origin xyz="0 0 0.05" rpy="0 0 0"/>
            <geometry>
                <cylinder length="0.1" radius="0.25"/>
            </geometry>
            <material name="green"/>
        </visual>

        <collision>
            <origin xyz="0 0 0.05" rpy="0 0 0"/>
            <geometry>
                <cylinder length="0.1" radius="0.25"/>
            </geometry>
            <!-- <contact_coefficient mu="0"  resitution="0"  k_p="0"  k_d="0" /> -->
        </collision>

        <inertial>
            <origin xyz="0 0 0.05" rpy="0 0 0"/>
            <mass value="0.1"/>
            <inertia ixx="1.7" ixy="0" ixz="0" iyy="1.7" iyz="0.0" izz="2.5"/>
        </inertial>
    </link>

    <joint name="hinge1" type="continuous">
        <origin xyz="0.0 0.0 0.0" rpy="0 0 0" />
        <parent link="world"/>
        <child link="intermediate"/>
        <axis xyz="1 0 0"/>
        <dynamics damping="0.0" friction="0.0"/>
    </joint>

    <joint name="hinge2" type="continuous">
        <origin xyz="0.0 0.0 0.0" rpy="0 0 1.57079" />
        <parent link="intermediate"/>
        <child link="pole"/>
        <axis xyz="1 0 0"/>
        <dynamics damping="0.0" friction="0.0"/>
    </joint>

    <joint name="pole to wheel" type="continuous">
        <origin xyz="0.0 0.0 1.0" rpy="0 0 0" />
        <parent link="pole"/>
        <child link="wheel"/>
        <axis xyz="0 0 1"/>
        <dynamics damping="0.0" friction="0.0"/>
        
    </joint>

</robot>